Workbook

Sheet Start_Here
A1: LifePath Career Exploration Assessment
A2: A strengths-based tool for exploration (not prediction). Designed for students ages 14–18, educators, and families.
A4: Student name: | C4: Date: | E4: Class/Advisor:
A7: How to complete the assessment (student steps)
A9: 1) Go to each section tab: Interests → Strengths → Drivers → Conditions.
A10: 2) In each section, fill in the yellow rating cells using the 1–4 scale.
A11: • 1 = Not me / Not true right now • 2 = A little like me • 3 = Mostly me • 4 = Very me
A12: 3) Try to answer all items. If you truly can’t answer one, leave it blank and come back later.
A13: 4) When each section shows 100% completion, open the “Results_Dashboard” tab.
A14: 5) Use the results to pick 2–3 paths to explore first (classes, clubs, job shadows, interviews).
A17: Important notes (read this)
A19: • This tool is for career exploration and conversation. It does not “decide” your future and it is not a diagnosis.
A20: • Your scores can change as you learn more about yourself and try new activities.
A21: • Use the results to expand choices: combine your top paths with electives, extracurriculars, or part-time work ideas.
A22: • If anything feels unfair or doesn’t fit your culture, values, or abilities, talk with an educator—your context matters.
... A29: Open: Sample_Report_Template

Sheet Interests
A1: INTERESTS – WHAT YOU ENJOY DOING | D1: Completion
A2: Rate how much each activity sounds like you — or how willing you would be to try it. | D2: Answered | E2: =COUNT(A10:A45) -> 36
A3: Answer based on your honest gut reaction. There are no right or wrong answers. | D3: Total | E3: 36
A4: If you have never tried something, rate how willing you would be to explore it. | D4: Percent | E4: =ROUND(E2/E3*100,0)&"%" -> 100%
A5: Try to answer every item. If you are truly stuck, skip and come back.
A6: Complete all 36 yellow cells before opening the Results Dashboard.
A8: ★ Scale: 1 = Not Like Me | 2 = A Little Like Me | 3 = Mostly Like Me | 4 = Very Like Me (If untried: rate your willingness to try it) | E8: Clinical Care Path | F8: Protection Path | G8: Learning & Support Path | H8: Build & Fix Path | I8: STEM Systems Path | J8: Business Growth & Leadership Path | K8: Creative Path | L8: Experience & Service Path | M8: Outdoor Systems Path
A9: Your Rating (1–4) | B9: Question | C9: Item | D9: LifePath | E9: CC | F9: PR | G9: LS | H9: BF | I9: SS | J9: BG | K9: CR | L9: ES | M9: OS
A10: 3 | B10: I'm curious about how the human body works and what helps people heal or recover. | C10: INT01 | D10: Clinical Care Path | E10: 1 | F10: 0 | G10: 0 | H10: 0 | I10: 0.25 | J10: 0 | K10: 0 | L10: 0 | M10: 0
A11: 3 | B11: I like learning about health topics like nutrition, mental health, fitness, or injury prevention. | C11: INT02 | D11: Clinical Care Path | E11: 1 | F11: 0 | G11: 0.25 | H11: 0 | I11: 0 | J11: 0 | K11: 0 | L11: 0 | M11: 0
A12: 3 | B12: I’m interested in clinical or care settings (clinics, hospitals, therapy, wellness). | C12: INT03 | D12: Clinical Care Path | E12: 1 | F12: 0 | G12: 0 | H12: 0 | I12: 0.25 | J12: 0 | K12: 0 | L12: 0 | M12: 0
A13: 2 | B13: I enjoy activities where I support or look after someone who is sick, injured, or going through a hard time. | C13: INT04 | D13: Clinical Care Path | E13: 1 | F13: 0 | G13: 0 | H13: 0.25 | I13: 0 | J13: 0 | K13: 0 | L13: 0 | M13: 0
A14: 2 | B14: I'm curious about how laws, rights, and rules protect people in real situations. | C14: INT05 | D14: Protection Path | E14: 0 | F14: 1 | G14: 0 | H14: 0 | I14: 0 | J14: 0.25 | K14: 0 | L14: 0 | M14: 0
A15: 1 | B15: I enjoy learning about safety, emergency response, or protecting the public. | C15: INT06 | D15: Protection Path | E15: 0 | F15: 1 | G15: 0 | H15: 0 | I15: 0.25 | J15: 0 | K15: 0 | L15: 0 | M15: 0
A16: 1 | B16: I’m interested in careers like policing, law, firefighting, or investigation. | C16: INT07 | D16: Protection Path | E16: 0 | F16: 1 | G16: 0 | H16: 0 | I16: 0 | J16: 0 | K16: 0 | L16: 0 | M16: 0
A17: 1 | B17: I like piecing together what happened using clues, timelines, and evidence. | C17: INT08 | D17: Protection Path | E17: 0 | F17: 1 | G17: 0 | H17: 0.25 | I17: 0 | J17: 0 | K17: 0 | L17: 0 | M17: 0
A18: 3 | B18: I enjoy helping someone practice or improve a skill and seeing them get better. | C18: INT09 | D18: Learning & Support Path | E18: 0 | F18: 0 | G18: 1 | H18: 0.25 | I18: 0 | J18: 0 | K18: 0 | L18: 0 | M18: 0
A19: 3 | B19: I’m curious about how kids, teens, or groups learn and grow. | C19: INT10 | D19: Learning & Support Path | E19: 0 | F19: 0 | G19: 1 | H19: 0 | I19: 0 | J19: 0 | K19: 0 | L19: 0.25 | M19: 0
A20: 4 | B20: I enjoy settings like classrooms, youth programs, or community centers where I help others learn or grow. | C20: INT11 | D20: Learning & Support Path | E20: 0 | F20: 0 | G20: 1 | H20: 0 | I20: 0 | J20: 0.25 | K20: 0 | L20: 0 | M20: 0
A21: 3 | B21: I enjoy figuring out people-problems—like how to motivate someone, resolve conflict, or build confidence. | C21: INT12 | D21: Learning & Support Path | E21: 0 | F21: 0 | G21: 1 | H21: 0 | I21: 0 | J21: 0 | K21: 0.25 | L21: 0 | M21: 0
... A45: 1 | B45: I enjoy hands-on nature work like growing, caring for, restoring, or protecting natural areas. | C45: INT36 | D45: Outdoor Systems Path | E45: 0.25 | F45: 0 | G45: 0 | H45: 0 | I45: 0 | J45: 0 | K45: 0 | L45: 0 | M45: 1
A48: RESULTS SUMMARY
A49: LifePath Type | B49: Composite Score (0–100) | C49: Fit Level | P49: Score (0–100)
A50: Clinical Care Path | B50: =ROUND((SUMPRODUCT($A$10:$A$45,$E$10:$E$45))/(4*SUM($E$10:$E$45))*100,0) -> 66 | C50: =IF(B50="","",IF(B50>=Admin_Settings!$B$3,Admin_Settings!$B$7,IF(B50>=Admin_Settings!$B$4,Admin_Settings!$B$8,IF(B50>=Admin_Settings!$B$5,Admin_Settings!$B$9,IF(B50>=Admin_Settings!$B$6,Admin_Settings!$B$10,Admin_Settings!$B$11))))) -> Moderate Fit | N50: =B50+ROW()/10000 -> 66.005 | O50: =INDEX($A$50:$A$58,MATCH(LARGE($N$50:$N$58,1),$N$50:$N$58,0)) -> Learning & Support Path | P50: =INDEX($B$50:$B$58,MATCH(LARGE($N$50:$N$58,1),$N$50:$N$58,0)) -> 79
A51: Protection Path | B51: =ROUND((SUMPRODUCT($A$10:$A$45,$F$10:$F$45))/(4*SUM($F$10:$F$45))*100,0) -> 31 | C51: =IF(B51="","",IF(B51>=Admin_Settings!$B$3,Admin_Settings!$B$7,IF(B51>=Admin_Settings!$B$4,Admin_Settings!$B$8,IF(B51>=Admin_Settings!$B$5,Admin_Settings!$B$9,IF(B51>=Admin_Settings!$B$6,Admin_Settings!$B$10,Admin_Settings!$B$11))))) -> Low Fit | N51: =B51+ROW()/10000 -> 31.0051 | O51: =INDEX($A$50:$A$58,MATCH(LARGE($N$50:$N$58,2),$N$50:$N$58,0)) -> Business Growth & Leadership Path | P51: =INDEX($B$50:$B$58,MATCH(LARGE($N$50:$N$58,2),$N$50:$N$58,0)) -> 75
A52: Learning & Support Path | B52: =ROUND((SUMPRODUCT($A$10:$A$45,$G$10:$G$45))/(4*SUM($G$10:$G$45))*100,0) -> 79 | C52: =IF(B52="","",IF(B52>=Admin_Settings!$B$3,Admin_Settings!$B$7,IF(B52>=Admin_Settings!$B$4,Admin_Settings!$B$8,IF(B52>=Admin_Settings!$B$5,Admin_Settings!$B$9,IF(B52>=Admin_Settings!$B$6,Admin_Settings!$B$10,Admin_Settings!$B$11))))) -> Strong Fit | N52: =B52+ROW()/10000 -> 79.0052 | O52: =INDEX($A$50:$A$58,MATCH(LARGE($N$50:$N$58,3),$N$50:$N$58,0)) -> Creative Path | P52: =INDEX($B$50:$B$58,MATCH(LARGE($N$50:$N$58,3),$N$50:$N$58,0)) -> 68
A53: Build & Fix Path | B53: =ROUND((SUMPRODUCT($A$10:$A$45,$H$10:$H$45))/(4*SUM($H$10:$H$45))*100,0) -> 44 | C53: =IF(B53="","",IF(B53>=Admin_Settings!$B$3,Admin_Settings!$B$7,IF(B53>=Admin_Settings!$B$4,Admin_Settings!$B$8,IF(B53>=Admin_Settings!$B$5,Admin_Settings!$B$9,IF(B53>=Admin_Settings!$B$6,Admin_Settings!$B$10,Admin_Settings!$B$11))))) -> Emerging Fit | N53: =B53+ROW()/10000 -> 44.0053 | O53: =INDEX($A$50:$A$58,MATCH(LARGE($N$50:$N$58,4),$N$50:$N$58,0)) -> Clinical Care Path | P53: =INDEX($B$50:$B$58,MATCH(LARGE($N$50:$N$58,4),$N$50:$N$58,0)) -> 66
A54: STEM Systems Path | B54: =ROUND((SUMPRODUCT($A$10:$A$45,$I$10:$I$45))/(4*SUM($I$10:$I$45))*100,0) -> 60 | C54: =IF(B54="","",IF(B54>=Admin_Settings!$B$3,Admin_Settings!$B$7,IF(B54>=Admin_Settings!$B$4,Admin_Settings!$B$8,IF(B54>=Admin_Settings!$B$5,Admin_Settings!$B$9,IF(B54>=Admin_Settings!$B$6,Admin_Settings!$B$10,Admin_Settings!$B$11))))) -> Moderate Fit | N54: =B54+ROW()/10000 -> 60.0054 | O54: =INDEX($A$50:$A$58,MATCH(LARGE($N$50:$N$58,5),$N$50:$N$58,0)) -> STEM Systems Path | P54: =INDEX($B$50:$B$58,MATCH(LARGE($N$50:$N$58,5),$N$50:$N$58,0)) -> 60
A55: Business Growth & Leadership Path | B55: =ROUND((SUMPRODUCT($A$10:$A$45,$J$10:$J$45))/(4*SUM($J$10:$J$45))*100,0) -> 75 | C55: =IF(B55="","",IF(B55>=Admin_Settings!$B$3,Admin_Settings!$B$7,IF(B55>=Admin_Settings!$B$4,Admin_Settings!$B$8,IF(B55>=Admin_Settings!$B$5,Admin_Settings!$B$9,IF(B55>=Admin_Settings!$B$6,Admin_Settings!$B$10,Admin_Settings!$B$11))))) -> Strong Fit | N55: =B55+ROW()/10000 -> 75.0055 | O55: =INDEX($A$50:$A$58,MATCH(LARGE($N$50:$N$58,6),$N$50:$N$58,0)) -> Experience & Service Path | P55: =INDEX($B$50:$B$58,MATCH(LARGE($N$50:$N$58,6),$N$50:$N$58,0)) -> 55
A56: Creative Path | B56: =ROUND((SUMPRODUCT($A$10:$A$45,$K$10:$K$45))/(4*SUM($K$10:$K$45))*100,0) -> 68 | C56: =IF(B56="","",IF(B56>=Admin_Settings!$B$3,Admin_Settings!$B$7,IF(B56>=Admin_Settings!$B$4,Admin_Settings!$B$8,IF(B56>=Admin_Settings!$B$5,Admin_Settings!$B$9,IF(B56>=Admin_Settings!$B$6,Admin_Settings!$B$10,Admin_Settings!$B$11))))) -> Moderate Fit | N56: =B56+ROW()/10000 -> 68.0056 | O56: =INDEX($A$50:$A$58,MATCH(LARGE($N$50:$N$58,7),$N$50:$N$58,0)) -> Build & Fix Path | P56: =INDEX($B$50:$B$58,MATCH(LARGE($N$50:$N$58,7),$N$50:$N$58,0)) -> 44
A57: Experience & Service Path | B57: =ROUND((SUMPRODUCT($A$10:$A$45,$L$10:$L$45))/(4*SUM($L$10:$L$45))*100,0) -> 55 | C57: =IF(B57="","",IF(B57>=Admin_Settings!$B$3,Admin_Settings!$B$7,IF(B57>=Admin_Settings!$B$4,Admin_Settings!$B$8,IF(B57>=Admin_Settings!$B$5,Admin_Settings!$B$9,IF(B57>=Admin_Settings!$B$6,Admin_Settings!$B$10,Admin_Settings!$B$11))))) -> Moderate Fit | N57: =B57+ROW()/10000 -> 55.0057 | O57: =INDEX($A$50:$A$58,MATCH(LARGE($N$50:$N$58,8),$N$50:$N$58,0)) -> Protection Path | P57: =INDEX($B$50:$B$58,MATCH(LARGE($N$50:$N$58,8),$N$50:$N$58,0)) -> 31
A58: Outdoor Systems Path | B58: =ROUND((SUMPRODUCT($A$10:$A$45,$M$10:$M$45))/(4*SUM($M$10:$M$45))*100,0) -> 25 | C58: =IF(B58="","",IF(B58>=Admin_Settings!$B$3,Admin_Settings!$B$7,IF(B58>=Admin_Settings!$B$4,Admin_Settings!$B$8,IF(B58>=Admin_Settings!$B$5,Admin_Settings!$B$9,IF(B58>=Admin_Settings!$B$6,Admin_Settings!$B$10,Admin_Settings!$B$11))))) -> Low Fit | N58: =B58+ROW()/10000 -> 25.0058 | O58: =INDEX($A$50:$A$58,MATCH(LARGE($N$50:$N$58,9),$N$50:$N$58,0)) -> Outdoor Systems Path | P58: =INDEX($B$50:$B$58,MATCH(LARGE($N$50:$N$58,9),$N$50:$N$58,0)) -> 25
A60: TOP 3 FITS
A61: Rank | B61: LifePath Type | C61: Score (0–100) | D61: Fit Level
A62: 1 | B62: =IFERROR(INDEX($A$50:$A$58,MATCH(LARGE($N$50:$N$58,1),$N$50:$N$58,0)),"") -> Learning & Support Path | C62: =IFERROR(INDEX($B$50:$B$58,MATCH(LARGE($N$50:$N$58,1),$N$50:$N$58,0)),"") -> 79 | D62: =IFERROR(INDEX($C$50:$C$58,MATCH(LARGE($N$50:$N$58,1),$N$50:$N$58,0)),"") -> Strong Fit
A63: 2 | B63: =IFERROR(INDEX($A$50:$A$58,MATCH(LARGE($N$50:$N$58,2),$N$50:$N$58,0)),"") -> Business Growth & Leadership Path | C63: =IFERROR(INDEX($B$50:$B$58,MATCH(LARGE($N$50:$N$58,2),$N$50:$N$58,0)),"") -> 75 | D63: =IFERROR(INDEX($C$50:$C$58,MATCH(LARGE($N$50:$N$58,2),$N$50:$N$58,0)),"") -> Strong Fit
A64: 3 | B64: =IFERROR(INDEX($A$50:$A$58,MATCH(LARGE($N$50:$N$58,3),$N$50:$N$58,0)),"") -> Creative Path | C64: =IFERROR(INDEX($B$50:$B$58,MATCH(LARGE($N$50:$N$58,3),$N$50:$N$58,0)),"") -> 68 | D64: =IFERROR(INDEX($C$50:$C$58,MATCH(LARGE($N$50:$N$58,3),$N$50:$N$58,0)),"") -> Moderate Fit
A66: RESULTS VISUAL

Sheet Strengths
A1: STRENGTHS – WHAT YOU CAN DO WELL | D1: Completion
A2: Rate how true each statement is for you right now. | D2: Answered | E2: =COUNT(A10:A45) -> 36
A3: If you have not tried something yet, rate how confident you feel you could learn it. | D3: Total | E3: 36
A4: Think about real examples from school, home, sports, work, or activities. | D4: Percent | E4: =ROUND(E2/E3*100,0)&"%" -> 100%
A5: Answer honestly — this is for you, not for a grade.
A6: Complete all 36 yellow cells before opening the Results Dashboard.
A8: ★ Scale: 1 = Not Like Me | 2 = A Little Like Me | 3 = Mostly Like Me | 4 = Very Like Me (If untried: rate your willingness to try it) | E8: Clinical Care Path | F8: Protection Path | G8: Learning & Support Path | H8: Build & Fix Path | I8: STEM Systems Path | J8: Business Growth & Leadership Path | K8: Creative Path | L8: Experience & Service Path | M8: Outdoor Systems Path
A9: Your Rating (1–4) | B9: Question | C9: Item | D9: LifePath | E9: CC | F9: PR | G9: LS | H9: BF | I9: SS | J9: BG | K9: CR | L9: ES | M9: OS
A10: 3 | B10: I can notice early warning signs that someone's health or safety is at risk and suggest a safe next step. | C10: STR01 | D10: Clinical Care Path | E10: 1 | F10: 0 | G10: 0 | H10: 0 | I10: 0 | J10: 0 | K10: 0 | L10: 0 | M10: 0
A11: 3 | B11: I can help someone feel calmer or more at ease when they're stressed, upset, or unwell. | C11: STR02 | D11: Clinical Care Path | E11: 1 | F11: 0 | G11: 0 | H11: 0 | I11: 0 | J11: 0 | K11: 0 | L11: 0 | M11: 0
A12: 3 | B12: I can follow careful procedures—like checking, documenting, or cleaning—so mistakes don't happen. | C12: STR03 | D12: Clinical Care Path | E12: 1 | F12: 0 | G12: 0 | H12: 0 | I12: 0 | J12: 0 | K12: 0 | L12: 0 | M12: 0
A13: 2 | B13: I can stay focused on details even when the situation feels serious or emotional. | C13: STR04 | D13: Clinical Care Path | E13: 1 | F13: 0 | G13: 0 | H13: 0 | I13: 0.25 | J13: 0 | K13: 0 | L13: 0 | M13: 0
A14: 2 | B14: I can stay calm and communicate clearly when there is conflict, urgency, or pressure. | C14: STR05 | D14: Protection Path | E14: 0 | F14: 1 | G14: 0 | H14: 0 | I14: 0 | J14: 0 | K14: 0 | L14: 0 | M14: 0
A15: 1 | B15: I can explain a rule or boundary in a way that feels fair and firm without being harsh. | C15: STR06 | D15: Protection Path | E15: 0 | F15: 1 | G15: 0 | H15: 0 | I15: 0 | J15: 0 | K15: 0 | L15: 0 | M15: 0
A16: 1 | B16: I can gather facts, check details, and describe events in the right order. | C16: STR07 | D16: Protection Path | E16: 0 | F16: 1 | G16: 0 | H16: 0 | I16: 0 | J16: 0 | K16: 0.25 | L16: 0 | M16: 0
A17: 1 | B17: I can make quick, safety-first decisions when something unexpected happens. | C17: STR08 | D17: Protection Path | E17: 0 | F17: 1 | G17: 0 | H17: 0 | I17: 0 | J17: 0 | K17: 0 | L17: 0 | M17: 0
A18: 3 | B18: I can break a skill down into clear, small steps that someone else can actually follow and learn. | C18: STR09 | D18: Learning & Support Path | E18: 0 | F18: 0 | G18: 1 | H18: 0 | I18: 0 | J18: 0 | K18: 0 | L18: 0 | M18: 0
A19: 3 | B19: I can encourage someone who’s struggling without judging them. | C19: STR10 | D19: Learning & Support Path | E19: 0 | F19: 0 | G19: 1 | H19: 0 | I19: 0 | J19: 0 | K19: 0 | L19: 0 | M19: 0
A20: 4 | B20: I can plan a simple activity, lesson, or group session so people know what to do and why. | C20: STR11 | D20: Learning & Support Path | E20: 0 | F20: 0 | G20: 1 | H20: 0 | I20: 0 | J20: 0 | K20: 0 | L20: 0 | M20: 0
A21: 3 | B21: I can notice what a person needs (support, challenge, or a break) and adjust my approach. | C21: STR12 | D21: Learning & Support Path | E21: 0 | F21: 0 | G21: 1 | H21: 0 | I21: 0 | J21: 0 | K21: 0 | L21: 0 | M21: 0
... A45: 1 | B45: I make choices that protect land, water, and living things—reduce waste, prevent damage, follow rules. | C45: STR36 | D45: Outdoor Systems Path | E45: 0 | F45: 0 | G45: 0 | H45: 0 | I45: 0 | J45: 0 | K45: 0 | L45: 0 | M45: 1
A48: RESULTS SUMMARY
A49: LifePath Type | B49: Composite Score (0–100) | C49: Fit Level | P49: Score (0–100)
A50: Clinical Care Path | B50: =ROUND((SUMPRODUCT($A$10:$A$45,$E$10:$E$45))/(4*SUM($E$10:$E$45))*100,0) -> 68 | C50: =IF(B50="","",IF(B50>=Admin_Settings!$B$3,Admin_Settings!$B$7,IF(B50>=Admin_Settings!$B$4,Admin_Settings!$B$8,IF(B50>=Admin_Settings!$B$5,Admin_Settings!$B$9,IF(B50>=Admin_Settings!$B$6,Admin_Settings!$B$10,Admin_Settings!$B$11))))) -> Moderate Fit | N50: =B50+ROW()/10000 -> 68.005 | O50: =INDEX($A$50:$A$58,MATCH(LARGE($N$50:$N$58,1),$N$50:$N$58,0)) -> Learning & Support Path | P50: =INDEX($B$50:$B$58,MATCH(LARGE($N$50:$N$58,1),$N$50:$N$58,0)) -> 80
A51: Protection Path | B51: =ROUND((SUMPRODUCT($A$10:$A$45,$F$10:$F$45))/(4*SUM($F$10:$F$45))*100,0) -> 33 | C51: =IF(B51="","",IF(B51>=Admin_Settings!$B$3,Admin_Settings!$B$7,IF(B51>=Admin_Settings!$B$4,Admin_Settings!$B$8,IF(B51>=Admin_Settings!$B$5,Admin_Settings!$B$9,IF(B51>=Admin_Settings!$B$6,Admin_Settings!$B$10,Admin_Settings!$B$11))))) -> Low Fit | N51: =B51+ROW()/10000 -> 33.0051 | O51: =INDEX($A$50:$A$58,MATCH(LARGE($N$50:$N$58,2),$N$50:$N$58,0)) -> Business Growth & Leadership Path | P51: =INDEX($B$50:$B$58,MATCH(LARGE($N$50:$N$58,2),$N$50:$N$58,0)) -> 78
A52: Learning & Support Path | B52: =ROUND((SUMPRODUCT($A$10:$A$45,$G$10:$G$45))/(4*SUM($G$10:$G$45))*100,0) -> 80 | C52: =IF(B52="","",IF(B52>=Admin_Settings!$B$3,Admin_Settings!$B$7,IF(B52>=Admin_Settings!$B$4,Admin_Settings!$B$8,IF(B52>=Admin_Settings!$B$5,Admin_Settings!$B$9,IF(B52>=Admin_Settings!$B$6,Admin_Settings!$B$10,Admin_Settings!$B$11))))) -> Strong Fit | N52: =B52+ROW()/10000 -> 80.0052 | O52: =INDEX($A$50:$A$58,MATCH(LARGE($N$50:$N$58,3),$N$50:$N$58,0)) -> Clinical Care Path | P52: =INDEX($B$50:$B$58,MATCH(LARGE($N$50:$N$58,3),$N$50:$N$58,0)) -> 68
A53: Build & Fix Path | B53: =ROUND((SUMPRODUCT($A$10:$A$45,$H$10:$H$45))/(4*SUM($H$10:$H$45))*100,0) -> 43 | C53: =IF(B53="","",IF(B53>=Admin_Settings!$B$3,Admin_Settings!$B$7,IF(B53>=Admin_Settings!$B$4,Admin_Settings!$B$8,IF(B53>=Admin_Settings!$B$5,Admin_Settings!$B$9,IF(B53>=Admin_Settings!$B$6,Admin_Settings!$B$10,Admin_Settings!$B$11))))) -> Emerging Fit | N53: =B53+ROW()/10000 -> 43.0053 | O53: =INDEX($A$50:$A$58,MATCH(LARGE($N$50:$N$58,4),$N$50:$N$58,0)) -> Creative Path | P53: =INDEX($B$50:$B$58,MATCH(LARGE($N$50:$N$58,4),$N$50:$N$58,0)) -> 66
A54: STEM Systems Path | B54: =ROUND((SUMPRODUCT($A$10:$A$45,$I$10:$I$45))/(4*SUM($I$10:$I$45))*100,0) -> 60 | C54: =IF(B54="","",IF(B54>=Admin_Settings!$B$3,Admin_Settings!$B$7,IF(B54>=Admin_Settings!$B$4,Admin_Settings!$B$8,IF(B54>=Admin_Settings!$B$5,Admin_Settings!$B$9,IF(B54>=Admin_Settings!$B$6,Admin_Settings!$B$10,Admin_Settings!$B$11))))) -> Moderate Fit | N54: =B54+ROW()/10000 -> 60.0054 | O54: =INDEX($A$50:$A$58,MATCH(LARGE($N$50:$N$58,5),$N$50:$N$58,0)) -> STEM Systems Path | P54: =INDEX($B$50:$B$58,MATCH(LARGE($N$50:$N$58,5),$N$50:$N$58,0)) -> 60
A55: Business Growth & Leadership Path | B55: =ROUND((SUMPRODUCT($A$10:$A$45,$J$10:$J$45))/(4*SUM($J$10:$J$45))*100,0) -> 78 | C55: =IF(B55="","",IF(B55>=Admin_Settings!$B$3,Admin_Settings!$B$7,IF(B55>=Admin_Settings!$B$4,Admin_Settings!$B$8,IF(B55>=Admin_Settings!$B$5,Admin_Settings!$B$9,IF(B55>=Admin_Settings!$B$6,Admin_Settings!$B$10,Admin_Settings!$B$11))))) -> Strong Fit | N55: =B55+ROW()/10000 -> 78.0055 | O55: =INDEX($A$50:$A$58,MATCH(LARGE($N$50:$N$58,6),$N$50:$N$58,0)) -> Experience & Service Path | P55: =INDEX($B$50:$B$58,MATCH(LARGE($N$50:$N$58,6),$N$50:$N$58,0)) -> 50
A56: Creative Path | B56: =ROUND((SUMPRODUCT($A$10:$A$45,$K$10:$K$45))/(4*SUM($K$10:$K$45))*100,0) -> 66 | C56: =IF(B56="","",IF(B56>=Admin_Settings!$B$3,Admin_Settings!$B$7,IF(B56>=Admin_Settings!$B$4,Admin_Settings!$B$8,IF(B56>=Admin_Settings!$B$5,Admin_Settings!$B$9,IF(B56>=Admin_Settings!$B$6,Admin_Settings!$B$10,Admin_Settings!$B$11))))) -> Moderate Fit | N56: =B56+ROW()/10000 -> 66.0056 | O56: =INDEX($A$50:$A$58,MATCH(LARGE($N$50:$N$58,7),$N$50:$N$58,0)) -> Build & Fix Path | P56: =INDEX($B$50:$B$58,MATCH(LARGE($N$50:$N$58,7),$N$50:$N$58,0)) -> 43
A57: Experience & Service Path | B57: =ROUND((SUMPRODUCT($A$10:$A$45,$L$10:$L$45))/(4*SUM($L$10:$L$45))*100,0) -> 50 | C57: =IF(B57="","",IF(B57>=Admin_Settings!$B$3,Admin_Settings!$B$7,IF(B57>=Admin_Settings!$B$4,Admin_Settings!$B$8,IF(B57>=Admin_Settings!$B$5,Admin_Settings!$B$9,IF(B57>=Admin_Settings!$B$6,Admin_Settings!$B$10,Admin_Settings!$B$11))))) -> Emerging Fit | N57: =B57+ROW()/10000 -> 50.0057 | O57: =INDEX($A$50:$A$58,MATCH(LARGE($N$50:$N$58,8),$N$50:$N$58,0)) -> Protection Path | P57: =INDEX($B$50:$B$58,MATCH(LARGE($N$50:$N$58,8),$N$50:$N$58,0)) -> 33
A58: Outdoor Systems Path | B58: =ROUND((SUMPRODUCT($A$10:$A$45,$M$10:$M$45))/(4*SUM($M$10:$M$45))*100,0) -> 25 | C58: =IF(B58="","",IF(B58>=Admin_Settings!$B$3,Admin_Settings!$B$7,IF(B58>=Admin_Settings!$B$4,Admin_Settings!$B$8,IF(B58>=Admin_Settings!$B$5,Admin_Settings!$B$9,IF(B58>=Admin_Settings!$B$6,Admin_Settings!$B$10,Admin_Settings!$B$11))))) -> Low Fit | N58: =B58+ROW()/10000 -> 25.0058 | O58: =INDEX($A$50:$A$58,MATCH(LARGE($N$50:$N$58,9),$N$50:$N$58,0)) -> Outdoor Systems Path | P58: =INDEX($B$50:$B$58,MATCH(LARGE($N$50:$N$58,9),$N$50:$N$58,0)) -> 25
A60: TOP 3 FITS
A61: Rank | B61: LifePath Type | C61: Score (0–100) | D61: Fit Level
A62: 1 | B62: =IFERROR(INDEX($A$50:$A$58,MATCH(LARGE($N$50:$N$58,1),$N$50:$N$58,0)),"") -> Learning & Support Path | C62: =IFERROR(INDEX($B$50:$B$58,MATCH(LARGE($N$50:$N$58,1),$N$50:$N$58,0)),"") -> 80 | D62: =IFERROR(INDEX($C$50:$C$58,MATCH(LARGE($N$50:$N$58,1),$N$50:$N$58,0)),"") -> Strong Fit
A63: 2 | B63: =IFERROR(INDEX($A$50:$A$58,MATCH(LARGE($N$50:$N$58,2),$N$50:$N$58,0)),"") -> Business Growth & Leadership Path | C63: =IFERROR(INDEX($B$50:$B$58,MATCH(LARGE($N$50:$N$58,2),$N$50:$N$58,0)),"") -> 78 | D63: =IFERROR(INDEX($C$50:$C$58,MATCH(LARGE($N$50:$N$58,2),$N$50:$N$58,0)),"") -> Strong Fit
A64: 3 | B64: =IFERROR(INDEX($A$50:$A$58,MATCH(LARGE($N$50:$N$58,3),$N$50:$N$58,0)),"") -> Clinical Care Path | C64: =IFERROR(INDEX($B$50:$B$58,MATCH(LARGE($N$50:$N$58,3),$N$50:$N$58,0)),"") -> 68 | D64: =IFERROR(INDEX($C$50:$C$58,MATCH(LARGE($N$50:$N$58,3),$N$50:$N$58,0)),"") -> Moderate Fit
A66: RESULTS VISUAL

Sheet Drivers
A1: DRIVERS (FUEL) – WHY YOU CARE | D1: Completion
A2: Rate how true each motivator feels for you right now. | D2: Answered | E2: =COUNT(A10:A45) -> 36
A3: Think about what actually energizes you, not what you think you should care about. | D3: Total | E3: 36
A4: There are no right or wrong answers — everyone is motivated by different things. | D4: Percent | E4: =ROUND(E2/E3*100,0)&"%" -> 100%
A5: Answer honestly and do not overthink your responses.
A6: Complete all 36 yellow cells before opening the Results Dashboard.
A8: ★ Scale: 1 = Not Like Me | 2 = A Little Like Me | 3 = Mostly Like Me | 4 = Very Like Me (If untried: rate your willingness to try it) | E8: Clinical Care Path | F8: Protection Path | G8: Learning & Support Path | H8: Build & Fix Path | I8: STEM Systems Path | J8: Business Growth & Leadership Path | K8: Creative Path | L8: Experience & Service Path | M8: Outdoor Systems Path
A9: Your Rating (1–4) | B9: Driver Statement | C9: Item | D9: LifePath | E9: CC | F9: PR | G9: LS | H9: BF | I9: SS | J9: BG | K9: CR | L9: ES | M9: OS
A10: 3 | B10: I feel fulfilled when my work directly helps someone heal, recover, or stay healthier. | C10: DRV01 | D10: Clinical Care Path | E10: 1 | F10: 0 | G10: 0 | H10: 0 | I10: 0 | J10: 0 | K10: 0 | L10: 0 | M10: 0
A11: 3 | B11: I'm motivated when I help someone recover from illness, injury, or a health crisis. | C11: DRV02 | D11: Clinical Care Path | E11: 1 | F11: 0 | G11: 0 | H11: 0 | I11: 0 | J11: 0 | K11: 0 | L11: 0 | M11: 0
A12: 3 | B12: I'm motivated to keep learning so I can give better care and catch things other people might miss. | C12: DRV03 | D12: Clinical Care Path | E12: 1 | F12: 0 | G12: 0 | H12: 0 | I12: 0 | J12: 0 | K12: 0 | L12: 0 | M12: 0
A13: 2 | B13: I’m motivated when I keep learning skills that make my care more effective. | C13: DRV04 | D13: Clinical Care Path | E13: 1 | F13: 0 | G13: 0 | H13: 0 | I13: 0 | J13: 0 | K13: 0 | L13: 0 | M13: 0
A14: 2 | B14: I feel a strong sense of purpose when I help prevent harm or protect people from danger. | C14: DRV05 | D14: Protection Path | E14: 0 | F14: 1 | G14: 0 | H14: 0 | I14: 0 | J14: 0 | K14: 0 | L14: 0 | M14: 0
A15: 1 | B15: It matters deeply to me to stand up for what's fair—even when it's hard. | C15: DRV06 | D15: Protection Path | E15: 0 | F15: 1 | G15: 0 | H15: 0 | I15: 0 | J15: 0 | K15: 0 | L15: 0 | M15: 0
A16: 1 | B16: I want to be the kind of person who stays steady under pressure. | C16: DRV07 | D16: Protection Path | E16: 0 | F16: 1 | G16: 0 | H16: 0 | I16: 0 | J16: 0 | K16: 0 | L16: 0 | M16: 0
A17: 1 | B17: I’m motivated when my work improves trust and safety in the community. | C17: DRV08 | D17: Protection Path | E17: 0 | F17: 1 | G17: 0 | H17: 0 | I17: 0 | J17: 0 | K17: 0 | L17: 0 | M17: 0
A18: 3 | B18: I feel fulfilled when someone grows more confident or capable because I helped them. | C18: DRV09 | D18: Learning & Support Path | E18: 0 | F18: 0 | G18: 1 | H18: 0 | I18: 0 | J18: 0 | K18: 0 | L18: 0 | M18: 0
A19: 3 | B19: It matters to me that people feel supported and respected while they're learning, not judged. | C19: DRV10 | D19: Learning & Support Path | E19: 0 | F19: 0 | G19: 1 | H19: 0 | I19: 0 | J19: 0 | K19: 0 | L19: 0 | M19: 0
A20: 4 | B20: I feel motivated when I help someone see a path forward—whether that's a student finding their confidence or a person getting connected to help they need. | C20: DRV11 | D20: Learning & Support Path | E20: 0 | F20: 0 | G20: 1 | H20: 0 | I20: 0 | J20: 0 | K20: 0 | L20: 0 | M20: 0
A21: 3 | B21: I'm motivated when I can contribute to stronger, more connected groups or communities over time. | C21: DRV12 | D21: Learning & Support Path | E21: 0 | F21: 0 | G21: 1 | H21: 0 | I21: 0 | J21: 0 | K21: 0 | L21: 0 | M21: 0
... A45: 1 | B45: I'm motivated by work that supports long-term sustainability, even when results take time to show. | C45: DRV36 | D45: Outdoor Systems Path | E45: 0 | F45: 0 | G45: 0 | H45: 0 | I45: 0 | J45: 0 | K45: 0 | L45: 0 | M45: 1
A46: CORE MOTIVATORS (ACROSS ALL PATHS) – Not part of LifePath scores
A47: Your Rating (1–4) | B47: Motivator Statement | C47: Item | D47: Category
B48: I want my work to help people in real, practical ways. | C48: M01 | D48: Helping People
B49: I like solving problems and making things work better. | C49: M02 | D49: Problem Solving
A50: Motivator Average | B50: =AVERAGE(A48:A49) -> #DIV/0!
A52: RESULTS SUMMARY
A53: LifePath Type | B53: Composite Score (0–100) | C53: Fit Level
A54: Clinical Care Path | B54: =ROUND((SUMPRODUCT($A$10:$A$45,$E$10:$E$45))/(4*SUM($E$10:$E$45))*100,0) -> 69 | C54: =IF(B54="","",IF(B54>=Admin_Settings!$B$3,Admin_Settings!$B$7,IF(B54>=Admin_Settings!$B$4,Admin_Settings!$B$8,IF(B54>=Admin_Settings!$B$5,Admin_Settings!$B$9,IF(B54>=Admin_Settings!$B$6,Admin_Settings!$B$10,Admin_Settings!$B$11))))) -> Moderate Fit
A55: Protection Path | B55: =ROUND((SUMPRODUCT($A$10:$A$45,$F$10:$F$45))/(4*SUM($F$10:$F$45))*100,0) -> 31 | C55: =IF(B55="","",IF(B55>=Admin_Settings!$B$3,Admin_Settings!$B$7,IF(B55>=Admin_Settings!$B$4,Admin_Settings!$B$8,IF(B55>=Admin_Settings!$B$5,Admin_Settings!$B$9,IF(B55>=Admin_Settings!$B$6,Admin_Settings!$B$10,Admin_Settings!$B$11))))) -> Low Fit
A56: Learning & Support Path | B56: =ROUND((SUMPRODUCT($A$10:$A$45,$G$10:$G$45))/(4*SUM($G$10:$G$45))*100,0) -> 81 | C56: =IF(B56="","",IF(B56>=Admin_Settings!$B$3,Admin_Settings!$B$7,IF(B56>=Admin_Settings!$B$4,Admin_Settings!$B$8,IF(B56>=Admin_Settings!$B$5,Admin_Settings!$B$9,IF(B56>=Admin_Settings!$B$6,Admin_Settings!$B$10,Admin_Settings!$B$11))))) -> Strong Fit
A57: Build & Fix Path | B57: =ROUND((SUMPRODUCT($A$10:$A$45,$H$10:$H$45))/(4*SUM($H$10:$H$45))*100,0) -> 44 | C57: =IF(B57="","",IF(B57>=Admin_Settings!$B$3,Admin_Settings!$B$7,IF(B57>=Admin_Settings!$B$4,Admin_Settings!$B$8,IF(B57>=Admin_Settings!$B$5,Admin_Settings!$B$9,IF(B57>=Admin_Settings!$B$6,Admin_Settings!$B$10,Admin_Settings!$B$11))))) -> Emerging Fit
A58: STEM Systems Path | B58: =ROUND((SUMPRODUCT($A$10:$A$45,$I$10:$I$45))/(4*SUM($I$10:$I$45))*100,0) -> 63 | C58: =IF(B58="","",IF(B58>=Admin_Settings!$B$3,Admin_Settings!$B$7,IF(B58>=Admin_Settings!$B$4,Admin_Settings!$B$8,IF(B58>=Admin_Settings!$B$5,Admin_Settings!$B$9,IF(B58>=Admin_Settings!$B$6,Admin_Settings!$B$10,Admin_Settings!$B$11))))) -> Moderate Fit
A59: Business Growth & Leadership Path | B59: =ROUND((SUMPRODUCT($A$10:$A$45,$J$10:$J$45))/(4*SUM($J$10:$J$45))*100,0) -> 81 | C59: =IF(B59="","",IF(B59>=Admin_Settings!$B$3,Admin_Settings!$B$7,IF(B59>=Admin_Settings!$B$4,Admin_Settings!$B$8,IF(B59>=Admin_Settings!$B$5,Admin_Settings!$B$9,IF(B59>=Admin_Settings!$B$6,Admin_Settings!$B$10,Admin_Settings!$B$11))))) -> Strong Fit
A60: Creative Path | B60: =ROUND((SUMPRODUCT($A$10:$A$45,$K$10:$K$45))/(4*SUM($K$10:$K$45))*100,0) -> 69 | C60: =IF(B60="","",IF(B60>=Admin_Settings!$B$3,Admin_Settings!$B$7,IF(B60>=Admin_Settings!$B$4,Admin_Settings!$B$8,IF(B60>=Admin_Settings!$B$5,Admin_Settings!$B$9,IF(B60>=Admin_Settings!$B$6,Admin_Settings!$B$10,Admin_Settings!$B$11))))) -> Moderate Fit
A61: Experience & Service Path | B61: =ROUND((SUMPRODUCT($A$10:$A$45,$L$10:$L$45))/(4*SUM($L$10:$L$45))*100,0) -> 50 | C61: =IF(B61="","",IF(B61>=Admin_Settings!$B$3,Admin_Settings!$B$7,IF(B61>=Admin_Settings!$B$4,Admin_Settings!$B$8,IF(B61>=Admin_Settings!$B$5,Admin_Settings!$B$9,IF(B61>=Admin_Settings!$B$6,Admin_Settings!$B$10,Admin_Settings!$B$11))))) -> Emerging Fit
A62: Outdoor Systems Path | B62: =ROUND((SUMPRODUCT($A$10:$A$45,$M$10:$M$45))/(4*SUM($M$10:$M$45))*100,0) -> 25 | C62: =IF(B62="","",IF(B62>=Admin_Settings!$B$3,Admin_Settings!$B$7,IF(B62>=Admin_Settings!$B$4,Admin_Settings!$B$8,IF(B62>=Admin_Settings!$B$5,Admin_Settings!$B$9,IF(B62>=Admin_Settings!$B$6,Admin_Settings!$B$10,Admin_Settings!$B$11))))) -> Low Fit

Sheet Work Style & Environment
A1: WORK STYLE & ENVIRONMENT – WHAT WORK FEELS LIKE | D1: Completion
A2: Rate each statement for what you would want on MOST work days — not just your best or worst day. This section is about preferred conditions, not current abilities. If two answers both feel true, choose what you would want MOST days. | D2: Answered | E2: =COUNT(A10:A45) -> 36
D3: Total | E3: 36
D4: Percent | E4: =ROUND(E2/E3*100,0)&"%" -> 100%
A6: Tip: Colors show the group for each statement. Look for patterns in your ratings.
A7: Your Rating (1–4)
A8: ★ Scale: 1 = Not Like Me | 2 = A Little Like Me | 3 = Mostly Like Me | 4 = Very Like Me (If untried: rate your willingness to try it) | H8: LifePath mapping (Primary/Secondary) | K8: Secondary weight (adaptive)
A9: Your Rating (1–4) | B9: Condition statement | C9: Item | D9: Construct | E9: Reverse? | F9: Scored | G9: ConstructCode | H9: Primary 1 | I9: Primary 2 | J9: Secondary | K9: Secondary Weight | L9: ItemWeight
A10: 4 | B10: I'm comfortable following detailed steps and procedures, even when they feel repetitive. | C10: CON01 | D10: Structure & Clarity | F10: =IF(A10="","",IF(E10="R",5-VALUE(A10),VALUE(A10))) -> 4 | G10: Pace_Change | H10: Clinical Care Path | I10: Build & Fix Path | J10: Protection Path | K10: 0.15 | L10: =IF($D10="Protection Signature",1.25,IF(OR($D10="Structure & Clarity",$D10="Quality vs Speed"),0.7,1)) -> 0.7
A11: 4 | B11: I like work that has clear standards I can measure my performance against. | C11: CON02 | D11: Structure & Clarity | F11: =IF(A11="","",IF(E11="R",5-VALUE(A11),VALUE(A11))) -> 4 | G11: Pace_Change | H11: Clinical Care Path | I11: STEM Systems Path | J11: Build & Fix Path | K11: 0.33 | L11: =IF($D11="Protection Signature",1.25,IF(OR($D11="Structure & Clarity",$D11="Quality vs Speed"),0.7,1)) -> 0.7
A12: 4 | B12: I’m okay starting without clear steps and figuring it out as I go. | C12: CON03 | D12: Structure & Clarity | E12: R | F12: =IF(A12="","",IF(E12="R",5-VALUE(A12),VALUE(A12))) -> 1 | G12: Pace_Change | H12: Creative Path | I12: Business Growth & Leadership Path | J12: STEM Systems Path | K12: 0.25 | L12: =IF($D12="Protection Signature",1.25,IF(OR($D12="Structure & Clarity",$D12="Quality vs Speed"),0.7,1)) -> 0.7
A13: 4 | B13: I enjoy days where I have to respond quickly to what comes up. | C13: CON04 | D13: Pace & Urgency | F13: =IF(A13="","",IF(E13="R",5-VALUE(A13),VALUE(A13))) -> 4 | G13: Pace_Change | H13: Experience & Service Path | I13: Business Growth & Leadership Path | L13: =IF($D13="Protection Signature",1.25,IF(OR($D13="Structure & Clarity",$D13="Quality vs Speed"),0.7,1)) -> 1
A14: 4 | B14: I like being in situations where I have to act quickly, even if it means I might make a small mistake. | C14: CON05 | D14: Pace & Urgency | F14: =IF(A14="","",IF(E14="R",5-VALUE(A14),VALUE(A14))) -> 4 | G14: Pressure_Responsibility | H14: Clinical Care Path | I14: Experience & Service Path | J14: Protection Path | K14: 0.15 | L14: =IF($D14="Protection Signature",1.25,IF(OR($D14="Structure & Clarity",$D14="Quality vs Speed"),0.7,1)) -> 1
A15: 4 | B15: I do my best work when I’m not rushed and can take my time to think. | C15: CON06 | D15: Pace & Urgency | E15: R | F15: =IF(A15="","",IF(E15="R",5-VALUE(A15),VALUE(A15))) -> 1 | G15: Pressure_Responsibility | H15: STEM Systems Path | I15: Learning & Support Path | J15: Creative Path | K15: 0.33 | L15: =IF($D15="Protection Signature",1.25,IF(OR($D15="Structure & Clarity",$D15="Quality vs Speed"),0.7,1)) -> 1
A16: 4 | B16: I strongly prefer to avoid conflict or tense situations whenever possible. | C16: CON07 | D16: Protection Contra | E16: R | F16: =IF(A16="","",IF(E16="R",5-VALUE(A16),VALUE(A16))) -> 1 | G16: Pressure_Responsibility | H16: Protection Path | L16: =IF($D16="Protection Signature",1.25,IF(OR($D16="Structure & Clarity",$D16="Quality vs Speed"),0.7,1)) -> 1
A17: 4 | B17: I'm okay repeating a process over and over to get really skilled at it. | C17: CON08 | D17: Variety vs Routine | E17: R | F17: =IF(A17="","",IF(E17="R",5-VALUE(A17),VALUE(A17))) -> 1 | G17: Pressure_Responsibility | H17: Build & Fix Path | I17: Clinical Care Path | J17: STEM Systems Path | K17: 0.33 | L17: =IF($D17="Protection Signature",1.25,IF(OR($D17="Structure & Clarity",$D17="Quality vs Speed"),0.7,1)) -> 1
A18: 4 | B18: I'm comfortable working within a clear chain of command where roles and authority are defined. | C18: CON09 | D18: Protection Signature | F18: =IF(A18="","",IF(E18="R",5-VALUE(A18),VALUE(A18))) -> 4 | G18: Structure_Rules | H18: Protection Path | L18: =IF($D18="Protection Signature",1.25,IF(OR($D18="Structure & Clarity",$D18="Quality vs Speed"),0.7,1)) -> 1.25
A19: 4 | B19: I like jobs where talking with people is a big part of the day. | C19: CON10 | D19: Social Energy | F19: =IF(A19="","",IF(E19="R",5-VALUE(A19),VALUE(A19))) -> 4 | G19: Structure_Rules | H19: Learning & Support Path | I19: Experience & Service Path | J19: Business Growth & Leadership Path | K19: 0.33 | L19: =IF($D19="Protection Signature",1.25,IF(OR($D19="Structure & Clarity",$D19="Quality vs Speed"),0.7,1)) -> 1
A20: 4 | B20: I do my best work in a quieter setting where I don't have to interact constantly. | C20: CON11 | D20: Social Energy | E20: R | F20: =IF(A20="","",IF(E20="R",5-VALUE(A20),VALUE(A20))) -> 1 | G20: Structure_Rules | H20: STEM Systems Path | I20: Creative Path | L20: =IF($D20="Protection Signature",1.25,IF(OR($D20="Structure & Clarity",$D20="Quality vs Speed"),0.7,1)) -> 1
A21: 4 | B21: I believe rules and standards should be applied consistently—even when it's unpopular. | C21: CON12 | D21: Protection Signature | F21: =IF(A21="","",IF(E21="R",5-VALUE(A21),VALUE(A21))) -> 4 | G21: Structure_Rules | H21: Protection Path | L21: =IF($D21="Protection Signature",1.25,IF(OR($D21="Structure & Clarity",$D21="Quality vs Speed"),0.7,1)) -> 1.25
A22: 4 | B22: I prefer working closely with teammates throughout the day rather than doing most of my work independently. | C22: CON13 | D22: Teamwork vs Solo Focus | F22: =IF(A22="","",IF(E22="R",5-VALUE(A22),VALUE(A22))) -> 4 | G22: Detail_Documentation | H22: Experience & Service Path | I22: Clinical Care Path | J22: Protection Path | K22: 0.15 | L22: =IF($D22="Protection Signature",1.25,IF(OR($D22="Structure & Clarity",$D22="Quality vs Speed"),0.7,1)) -> 1
A23: 4 | B23: I prefer doing my part independently and checking in later. | C23: CON14 | D23: Teamwork vs Solo Focus | E23: R | F23: =IF(A23="","",IF(E23="R",5-VALUE(A23),VALUE(A23))) -> 1 | G23: Detail_Documentation | H23: STEM Systems Path | I23: Outdoor Systems Path | J23: Creative Path | K23: 0.25 | L23: =IF($D23="Protection Signature",1.25,IF(OR($D23="Structure & Clarity",$D23="Quality vs Speed"),0.7,1)) -> 1
A24: 4 | B24: I like solving problems by talking them through with others and building on each other's ideas. | C24: CON15 | D24: Teamwork vs Solo Focus | F24: =IF(A24="","",IF(E24="R",5-VALUE(A24),VALUE(A24))) -> 4 | G24: Detail_Documentation | H24: Business Growth & Leadership Path | I24: Learning & Support Path | J24: Experience & Service Path | K24: 0.33 | L24: =IF($D24="Protection Signature",1.25,IF(OR($D24="Structure & Clarity",$D24="Quality vs Speed"),0.7,1)) -> 1
A25: 4 | B25: I do my best work when I can choose my own approach to getting something done. | C25: CON16 | D25: Independence & Autonomy | F25: =IF(A25="","",IF(E25="R",5-VALUE(A25),VALUE(A25))) -> 4 | G25: Detail_Documentation | H25: Creative Path | I25: Business Growth & Leadership Path | J25: Outdoor Systems Path | K25: 0.33 | L25: =IF($D25="Protection Signature",1.25,IF(OR($D25="Structure & Clarity",$D25="Quality vs Speed"),0.7,1)) -> 1
A26: 4 | B26: I do best when someone gives me clear steps to follow. | C26: CON17 | D26: Independence & Autonomy | E26: R | F26: =IF(A26="","",IF(E26="R",5-VALUE(A26),VALUE(A26))) -> 1 | G26: Social_Energy | H26: Clinical Care Path | I26: Build & Fix Path | J26: Protection Path | K26: 0.15 | L26: =IF($D26="Protection Signature",1.25,IF(OR($D26="Structure & Clarity",$D26="Quality vs Speed"),0.7,1)) -> 1
A27: 4 | B27: I like being responsible for the whole outcome, not just one piece. | C27: CON18 | D27: Independence & Autonomy | F27: =IF(A27="","",IF(E27="R",5-VALUE(A27),VALUE(A27))) -> 4 | G27: Social_Energy | H27: Business Growth & Leadership Path | I27: Creative Path | J27: STEM Systems Path | K27: 0.33 | L27: =IF($D27="Protection Signature",1.25,IF(OR($D27="Structure & Clarity",$D27="Quality vs Speed"),0.7,1)) -> 1
A28: 4 | B28: I can stay composed and think clearly when the stakes feel high. | C28: CON19 | D28: Comfort With Pressure | F28: =IF(A28="","",IF(E28="R",5-VALUE(A28),VALUE(A28))) -> 4 | G28: Social_Energy | H28: Clinical Care Path | I28: Experience & Service Path | J28: Protection Path | K28: 0.15 | L28: =IF($D28="Protection Signature",1.25,IF(OR($D28="Structure & Clarity",$D28="Quality vs Speed"),0.7,1)) -> 1
A29: 4 | B29: When things get urgent, it’s hard for me to stay steady and think clearly. | C29: CON20 | D29: Comfort With Pressure | E29: R | F29: =IF(A29="","",IF(E29="R",5-VALUE(A29),VALUE(A29))) -> 1 | G29: Social_Energy | H29: Protection Path | I29: Experience & Service Path | J29: Clinical Care Path | K29: 0.25 | L29: =IF($D29="Protection Signature",1.25,IF(OR($D29="Structure & Clarity",$D29="Quality vs Speed"),0.7,1)) -> 1
A30: 4 | B30: I can keep making clear-headed decisions even when the emotional stakes are high—like when someone is angry or in trouble. | C30: CON21 | D30: Comfort With Pressure | F30: =IF(A30="","",IF(E30="R",5-VALUE(A30),VALUE(A30))) -> 4 | G30: Conflict_Firmness | H30: Business Growth & Leadership Path | I30: Clinical Care Path | J30: Protection Path | K30: 0.15 | L30: =IF($D30="Protection Signature",1.25,IF(OR($D30="Structure & Clarity",$D30="Quality vs Speed"),0.7,1)) -> 1
A31: 4 | B31: I can stay calm and respectful during a tense or confrontational situation with another person. | C31: CON22 | D31: Protection Signature | F31: =IF(A31="","",IF(E31="R",5-VALUE(A31),VALUE(A31))) -> 4 | G31: Conflict_Firmness | H31: Protection Path | L31: =IF($D31="Protection Signature",1.25,IF(OR($D31="Structure & Clarity",$D31="Quality vs Speed"),0.7,1)) -> 1.25
A32: 4 | B32: Frequent interruptions make it hard for me to do my best work. | C32: CON23 | D32: Attention Environment | E32: R | F32: =IF(A32="","",IF(E32="R",5-VALUE(A32),VALUE(A32))) -> 1 | G32: Conflict_Firmness | H32: STEM Systems Path | I32: Creative Path | J32: Build & Fix Path | K32: 0.33 | L32: =IF($D32="Protection Signature",1.25,IF(OR($D32="Structure & Clarity",$D32="Quality vs Speed"),0.7,1)) -> 1
A33: 4 | B33: I can keep my attention on my task even in a busy place. | C33: CON24 | D33: Attention Environment | F33: =IF(A33="","",IF(E33="R",5-VALUE(A33),VALUE(A33))) -> 4 | G33: Conflict_Firmness | H33: Clinical Care Path | I33: Experience & Service Path | J33: Build & Fix Path | K33: 0.33 | L33: =IF($D33="Protection Signature",1.25,IF(OR($D33="Structure & Clarity",$D33="Quality vs Speed"),0.7,1)) -> 1
A34: 4 | B34: I prefer work where I’m moving around, not sitting all day. | C34: CON25 | D34: Work Setting | F34: =IF(A34="","",IF(E34="R",5-VALUE(A34),VALUE(A34))) -> 4 | G34: Sensory_BusyNoise | H34: Build & Fix Path | I34: Outdoor Systems Path | J34: Experience & Service Path | K34: 0.33 | L34: =IF($D34="Protection Signature",1.25,IF(OR($D34="Structure & Clarity",$D34="Quality vs Speed"),0.7,1)) -> 1
A35: 4 | B35: I prefer desk-based work where I’m mostly in one place. | C35: CON26 | D35: Work Setting | E35: R | F35: =IF(A35="","",IF(E35="R",5-VALUE(A35),VALUE(A35))) -> 1 | G35: Sensory_BusyNoise | H35: STEM Systems Path | I35: Business Growth & Leadership Path | J35: Creative Path | K35: 0.33 | L35: =IF($D35="Protection Signature",1.25,IF(OR($D35="Structure & Clarity",$D35="Quality vs Speed"),0.7,1)) -> 1
A36: 4 | B36: I don’t mind working in weather or changing outdoor conditions. | C36: CON27 | D36: Work Setting | F36: =IF(A36="","",IF(E36="R",5-VALUE(A36),VALUE(A36))) -> 4 | G36: Sensory_BusyNoise | H36: Outdoor Systems Path | I36: Build & Fix Path | L36: =IF($D36="Protection Signature",1.25,IF(OR($D36="Structure & Clarity",$D36="Quality vs Speed"),0.7,1)) -> 1
A37: 4 | B37: I prefer solving problems using facts, data, or careful planning rather than gut instinct. | C37: CON28 | D37: Problem Style | F37: =IF(A37="","",IF(E37="R",5-VALUE(A37),VALUE(A37))) -> 4 | G37: Sensory_BusyNoise | H37: STEM Systems Path | I37: Clinical Care Path | J37: Protection Path | K37: 0.15 | L37: =IF($D37="Protection Signature",1.25,IF(OR($D37="Structure & Clarity",$D37="Quality vs Speed"),0.7,1)) -> 1
A38: 4 | B38: I prefer hands-on tasks like building, fixing, or operating equipment. | C38: CON29 | D38: Problem Style | F38: =IF(A38="","",IF(E38="R",5-VALUE(A38),VALUE(A38))) -> 4 | G38: Physical_HandsOn | H38: Build & Fix Path | I38: Outdoor Systems Path | J38: Experience & Service Path | K38: 0.33 | L38: =IF($D38="Protection Signature",1.25,IF(OR($D38="Structure & Clarity",$D38="Quality vs Speed"),0.7,1)) -> 1
A39: 4 | B39: I prefer solving problems by creating something new—like sketching a solution, writing a plan, or designing a better process. | C39: CON30 | D39: Problem Style | F39: =IF(A39="","",IF(E39="R",5-VALUE(A39),VALUE(A39))) -> 4 | G39: Physical_HandsOn | H39: Creative Path | I39: Business Growth & Leadership Path | J39: STEM Systems Path | K39: 0.33 | L39: =IF($D39="Protection Signature",1.25,IF(OR($D39="Structure & Clarity",$D39="Quality vs Speed"),0.7,1)) -> 1
A40: 4 | B40: I like receiving feedback during a project so I can adjust and improve as I go. | C40: CON31 | D40: Feedback & Support | F40: =IF(A40="","",IF(E40="R",5-VALUE(A40),VALUE(A40))) -> 4 | G40: Physical_HandsOn | H40: Creative Path | I40: Learning & Support Path | J40: STEM Systems Path | K40: 0.33 | L40: =IF($D40="Protection Signature",1.25,IF(OR($D40="Structure & Clarity",$D40="Quality vs Speed"),0.7,1)) -> 1
A41: 4 | B41: I remember details well and can write down what happened clearly and accurately. | C41: CON32 | D41: Protection Signature | F41: =IF(A41="","",IF(E41="R",5-VALUE(A41),VALUE(A41))) -> 4 | G41: Physical_HandsOn | H41: Protection Path | L41: =IF($D41="Protection Signature",1.25,IF(OR($D41="Structure & Clarity",$D41="Quality vs Speed"),0.7,1)) -> 1.25
...

Sheet Results_Dashboard
A1: LifePath Results – Your Exploration Snapshot
A2: These results show your strongest starting points right now — not a final answer. Use them to explore, ask questions, and try things. Your scores can shift as you grow.
A4: Completion Check | D4: Section Weights (edit if needed) | J4: Your Top 3 Starting Points
A5: Interests | B5: =COUNT(Interests!$A$10:$A$45)/36 -> 1 | D5: Interests weight | E5: 0.35 | J5: Rank | K5: LifePath | L5: Overall
A6: Strengths | B6: =COUNT(Strengths!$A$10:$A$45)/36 -> 1 | D6: Strengths weight | E6: 0.35 | J6: 1 | K6: =IF($B$9=0,"",INDEX($A$13:$A$21,MATCH(LARGE($O$13:$O$21,1),$O$13:$O$21,0))) -> Learning & Support Path | L6: =IF($B$9=0,"",INDEX($F$13:$F$21,MATCH(LARGE($O$13:$O$21,1),$O$13:$O$21,0))) -> 80
A7: Drivers | B7: =COUNT(Drivers!$A$10:$A$45)/36 -> 1 | D7: Drivers weight | E7: 0.2 | J7: 2 | K7: =IF($B$9=0,"",INDEX($A$13:$A$21,MATCH(LARGE($O$13:$O$21,2),$O$13:$O$21,0))) -> Business Growth & Leadership Path | L7: =IF($B$9=0,"",INDEX($F$13:$F$21,MATCH(LARGE($O$13:$O$21,2),$O$13:$O$21,0))) -> 78
A8: Work Style & Environment | B8: =COUNT('Work Style & Environment'!$A$10:$A$45)/36 -> 1 | D8: Work Style & Environment weight | E8: 0.1 | J8: 3 | K8: =IF($B$9=0,"",INDEX($A$13:$A$21,MATCH(LARGE($O$13:$O$21,3),$O$13:$O$21,0))) -> Clinical Care Path | L8: =IF($B$9=0,"",INDEX($F$13:$F$21,MATCH(LARGE($O$13:$O$21,3),$O$13:$O$21,0))) -> 69
A9: All sections complete? | B9: =--AND(B5=1,B6=1,B7=1,B8=1) -> 1 | D9: Check (should = 1.00) | E9: =SUM(E5:E8) -> 1
J10: Why these showed up: | K10: =IF($B$9=0,"Complete all four sections to unlock your results.","Your results blend what you enjoy (Interests 35%), can do (Strengths 35%), care about (Drivers 20%), and how you prefer to work (Work Style 10%). No single section decides the outcome.") -> Your results blend what you enjoy (Interests 35%), can do (Strengths 35%), care about (Drivers 20%), and how you prefer to work (Work Style 10%). No single section decides the outcome.
A11: Overall LifePath Fit (combined across sections)
A12: LifePath Type | B12: Interests | C12: Strengths | D12: Drivers | E12: Work Style & Environment Fit | F12: Overall | G12: Signal Strength | H12: What this path is about | I12: Interests (weighted) | J12: Strengths (weighted) | K12: Drivers (weighted) | L12: Work Style & Environment (weighted) | M12: Top Contributors
A13: Clinical Care Path | B13: =IF(B5<1,"",IF(Interests!$B$50="","",Interests!$B$50)) -> 66 | C13: =IF(B6<1,"",IF(Strengths!$B$50="","",Strengths!$B$50)) -> 68 | D13: =IF(B7<1,"",IF(Drivers!$B$54="","",Drivers!$B$54)) -> 69 | E13: =IF(B8<1,"",IF('Work Style & Environment'!$B$64="","",'Work Style & Environment'!$B$64)) -> 81 | F13: =IF($B$9=0,"",ROUND(B13*$E$5 + C13*$E$6 + D13*$E$7 + E13*$E$8,0)) -> 69 | G13: =IF($B$9=0,"",IF(F13>=Admin_Settings!$B$3,Admin_Settings!$B$7,IF(F13>=Admin_Settings!$B$4,Admin_Settings!$B$8,IF(F13>=Admin_Settings!$B$5,Admin_Settings!$B$9,IF(F13>=Admin_Settings!$B$6,Admin_Settings!$B$10,Admin_Settings!$B$11))))) -> Moderate Fit | H13: Helping people heal through nursing, therapy, medicine, or mental health care. You work directly with patients in clinical settings using careful procedures and science-based methods. | I13: =IF($B$9=0,"",ROUND(B13*$E$5,1)) -> 23.1 | J13: =IF($B$9=0,"",ROUND(C13*$E$6,1)) -> 23.8 | K13: =IF($B$9=0,"",ROUND(D13*$E$7,1)) -> 13.8 | L13: =IF($B$9=0,"",ROUND(E13*$E$8,1)) -> 8.1 | M13: =IF($B$9=0,"","Top: " & IF(MAX(I13:L13)=I13,"Interests",IF(MAX(I13:L13)=J13,"Strengths",IF(MAX(I13:L13)=K13,"Drivers","Work Style & Environment")))) -> Top: Strengths | O13: =IF($B$9=0,"",$F13+(13-13)/1000000) -> 69
A14: Protection Path | B14: =IF(B5<1,"",IF(Interests!$B$51="","",Interests!$B$51)) -> 31 | C14: =IF(B6<1,"",IF(Strengths!$B$51="","",Strengths!$B$51)) -> 33 | D14: =IF(B7<1,"",IF(Drivers!$B$55="","",Drivers!$B$55)) -> 31 | E14: =IF(B8<1,"",IF('Work Style & Environment'!$B$65="","",'Work Style & Environment'!$B$65)) -> 66 | F14: =IF($B$9=0,"",ROUND(B14*$E$5 + C14*$E$6 + D14*$E$7 + E14*$E$8,0)) -> 35 | G14: =IF($B$9=0,"",IF(F14>=Admin_Settings!$B$3,Admin_Settings!$B$7,IF(F14>=Admin_Settings!$B$4,Admin_Settings!$B$8,IF(F14>=Admin_Settings!$B$5,Admin_Settings!$B$9,IF(F14>=Admin_Settings!$B$6,Admin_Settings!$B$10,Admin_Settings!$B$11))))) -> Low Fit | H14: Keeping communities safe through policing, firefighting, emergency response, investigations, or legal compliance. You make decisions under pressure and uphold fairness and the rule of law. | I14: =IF($B$9=0,"",ROUND(B14*$E$5,1)) -> 10.9 | J14: =IF($B$9=0,"",ROUND(C14*$E$6,1)) -> 11.6 | K14: =IF($B$9=0,"",ROUND(D14*$E$7,1)) -> 6.2 | L14: =IF($B$9=0,"",ROUND(E14*$E$8,1)) -> 6.6 | M14: =IF($B$9=0,"","Top: " & IF(MAX(I14:L14)=I14,"Interests",IF(MAX(I14:L14)=J14,"Strengths",IF(MAX(I14:L14)=K14,"Drivers","Work Style & Environment")))) -> Top: Strengths | O14: =IF($B$9=0,"",$F14+(14-13)/1000000) -> 35.000001
A15: Learning & Support Path | B15: =IF(B5<1,"",IF(Interests!$B$52="","",Interests!$B$52)) -> 79 | C15: =IF(B6<1,"",IF(Strengths!$B$52="","",Strengths!$B$52)) -> 80 | D15: =IF(B7<1,"",IF(Drivers!$B$56="","",Drivers!$B$56)) -> 81 | E15: =IF(B8<1,"",IF('Work Style & Environment'!$B$66="","",'Work Style & Environment'!$B$66)) -> 80 | F15: =IF($B$9=0,"",ROUND(B15*$E$5 + C15*$E$6 + D15*$E$7 + E15*$E$8,0)) -> 80 | G15: =IF($B$9=0,"",IF(F15>=Admin_Settings!$B$3,Admin_Settings!$B$7,IF(F15>=Admin_Settings!$B$4,Admin_Settings!$B$8,IF(F15>=Admin_Settings!$B$5,Admin_Settings!$B$9,IF(F15>=Admin_Settings!$B$6,Admin_Settings!$B$10,Admin_Settings!$B$11))))) -> Strong Fit | H15: Helping others learn, grow, and overcome challenges through teaching, counseling, coaching, or community programs. You build trust over time and take pride in watching people progress. | I15: =IF($B$9=0,"",ROUND(B15*$E$5,1)) -> 27.7 | J15: =IF($B$9=0,"",ROUND(C15*$E$6,1)) -> 28 | K15: =IF($B$9=0,"",ROUND(D15*$E$7,1)) -> 16.2 | L15: =IF($B$9=0,"",ROUND(E15*$E$8,1)) -> 8 | M15: =IF($B$9=0,"","Top: " & IF(MAX(I15:L15)=I15,"Interests",IF(MAX(I15:L15)=J15,"Strengths",IF(MAX(I15:L15)=K15,"Drivers","Work Style & Environment")))) -> Top: Strengths | O15: =IF($B$9=0,"",$F15+(15-13)/1000000) -> 80.000002
A16: Build & Fix Path | B16: =IF(B5<1,"",IF(Interests!$B$53="","",Interests!$B$53)) -> 44 | C16: =IF(B6<1,"",IF(Strengths!$B$53="","",Strengths!$B$53)) -> 43 | D16: =IF(B7<1,"",IF(Drivers!$B$57="","",Drivers!$B$57)) -> 44 | E16: =IF(B8<1,"",IF('Work Style & Environment'!$B$67="","",'Work Style & Environment'!$B$67)) -> 70 | F16: =IF($B$9=0,"",ROUND(B16*$E$5 + C16*$E$6 + D16*$E$7 + E16*$E$8,0)) -> 46 | G16: =IF($B$9=0,"",IF(F16>=Admin_Settings!$B$3,Admin_Settings!$B$7,IF(F16>=Admin_Settings!$B$4,Admin_Settings!$B$8,IF(F16>=Admin_Settings!$B$5,Admin_Settings!$B$9,IF(F16>=Admin_Settings!$B$6,Admin_Settings!$B$10,Admin_Settings!$B$11))))) -> Emerging Fit | H16: Building, repairing, and maintaining physical things using tools, equipment, and skilled techniques. You work in trades, construction, mechanics, manufacturing, or transportation. | I16: =IF($B$9=0,"",ROUND(B16*$E$5,1)) -> 15.4 | J16: =IF($B$9=0,"",ROUND(C16*$E$6,1)) -> 15.1 | K16: =IF($B$9=0,"",ROUND(D16*$E$7,1)) -> 8.8 | L16: =IF($B$9=0,"",ROUND(E16*$E$8,1)) -> 7 | M16: =IF($B$9=0,"","Top: " & IF(MAX(I16:L16)=I16,"Interests",IF(MAX(I16:L16)=J16,"Strengths",IF(MAX(I16:L16)=K16,"Drivers","Work Style & Environment")))) -> Top: Interests | O16: =IF($B$9=0,"",$F16+(16-13)/1000000) -> 46.000003
A17: STEM Systems Path | B17: =IF(B5<1,"",IF(Interests!$B$54="","",Interests!$B$54)) -> 60 | C17: =IF(B6<1,"",IF(Strengths!$B$54="","",Strengths!$B$54)) -> 60 | D17: =IF(B7<1,"",IF(Drivers!$B$58="","",Drivers!$B$58)) -> 63 | E17: =IF(B8<1,"",IF('Work Style & Environment'!$B$68="","",'Work Style & Environment'!$B$68)) -> 38 | F17: =IF($B$9=0,"",ROUND(B17*$E$5 + C17*$E$6 + D17*$E$7 + E17*$E$8,0)) -> 58 | G17: =IF($B$9=0,"",IF(F17>=Admin_Settings!$B$3,Admin_Settings!$B$7,IF(F17>=Admin_Settings!$B$4,Admin_Settings!$B$8,IF(F17>=Admin_Settings!$B$5,Admin_Settings!$B$9,IF(F17>=Admin_Settings!$B$6,Admin_Settings!$B$10,Admin_Settings!$B$11))))) -> Moderate Fit | H17: Solving real-world problems by designing, testing, and improving technical systems — software, engineering, robotics, data, or applied science. You enjoy logic, experimentation, and making things work better. | I17: =IF($B$9=0,"",ROUND(B17*$E$5,1)) -> 21 | J17: =IF($B$9=0,"",ROUND(C17*$E$6,1)) -> 21 | K17: =IF($B$9=0,"",ROUND(D17*$E$7,1)) -> 12.6 | L17: =IF($B$9=0,"",ROUND(E17*$E$8,1)) -> 3.8 | M17: =IF($B$9=0,"","Top: " & IF(MAX(I17:L17)=I17,"Interests",IF(MAX(I17:L17)=J17,"Strengths",IF(MAX(I17:L17)=K17,"Drivers","Work Style & Environment")))) -> Top: Interests | O17: =IF($B$9=0,"",$F17+(17-13)/1000000) -> 58.000004
A18: Business Growth & Leadership Path | B18: =IF(B5<1,"",IF(Interests!$B$55="","",Interests!$B$55)) -> 75 | C18: =IF(B6<1,"",IF(Strengths!$B$55="","",Strengths!$B$55)) -> 78 | D18: =IF(B7<1,"",IF(Drivers!$B$59="","",Drivers!$B$59)) -> 81 | E18: =IF(B8<1,"",IF('Work Style & Environment'!$B$69="","",'Work Style & Environment'!$B$69)) -> 79 | F18: =IF($B$9=0,"",ROUND(B18*$E$5 + C18*$E$6 + D18*$E$7 + E18*$E$8,0)) -> 78 | G18: =IF($B$9=0,"",IF(F18>=Admin_Settings!$B$3,Admin_Settings!$B$7,IF(F18>=Admin_Settings!$B$4,Admin_Settings!$B$8,IF(F18>=Admin_Settings!$B$5,Admin_Settings!$B$9,IF(F18>=Admin_Settings!$B$6,Admin_Settings!$B$10,Admin_Settings!$B$11))))) -> Strong Fit | H18: Organizing people, plans, and resources to reach goals and grow organizations. You work in management, marketing, finance, entrepreneurship, or operations — making decisions that create results. | I18: =IF($B$9=0,"",ROUND(B18*$E$5,1)) -> 26.3 | J18: =IF($B$9=0,"",ROUND(C18*$E$6,1)) -> 27.3 | K18: =IF($B$9=0,"",ROUND(D18*$E$7,1)) -> 16.2 | L18: =IF($B$9=0,"",ROUND(E18*$E$8,1)) -> 7.9 | M18: =IF($B$9=0,"","Top: " & IF(MAX(I18:L18)=I18,"Interests",IF(MAX(I18:L18)=J18,"Strengths",IF(MAX(I18:L18)=K18,"Drivers","Work Style & Environment")))) -> Top: Strengths | O18: =IF($B$9=0,"",$F18+(18-13)/1000000) -> 78.000005
A19: Creative Path | B19: =IF(B5<1,"",IF(Interests!$B$56="","",Interests!$B$56)) -> 68 | C19: =IF(B6<1,"",IF(Strengths!$B$56="","",Strengths!$B$56)) -> 66 | D19: =IF(B7<1,"",IF(Drivers!$B$60="","",Drivers!$B$60)) -> 69 | E19: =IF(B8<1,"",IF('Work Style & Environment'!$B$70="","",'Work Style & Environment'!$B$70)) -> 53 | F19: =IF($B$9=0,"",ROUND(B19*$E$5 + C19*$E$6 + D19*$E$7 + E19*$E$8,0)) -> 66 | G19: =IF($B$9=0,"",IF(F19>=Admin_Settings!$B$3,Admin_Settings!$B$7,IF(F19>=Admin_Settings!$B$4,Admin_Settings!$B$8,IF(F19>=Admin_Settings!$B$5,Admin_Settings!$B$9,IF(F19>=Admin_Settings!$B$6,Admin_Settings!$B$10,Admin_Settings!$B$11))))) -> Moderate Fit | H19: Creating designs, stories, media, music, or content that connects with people and communicates ideas. You refine your craft, express original ideas, and take pride in work that has impact. | I19: =IF($B$9=0,"",ROUND(B19*$E$5,1)) -> 23.8 | J19: =IF($B$9=0,"",ROUND(C19*$E$6,1)) -> 23.1 | K19: =IF($B$9=0,"",ROUND(D19*$E$7,1)) -> 13.8 | L19: =IF($B$9=0,"",ROUND(E19*$E$8,1)) -> 5.3 | M19: =IF($B$9=0,"","Top: " & IF(MAX(I19:L19)=I19,"Interests",IF(MAX(I19:L19)=J19,"Strengths",IF(MAX(I19:L19)=K19,"Drivers","Work Style & Environment")))) -> Top: Interests | O19: =IF($B$9=0,"",$F19+(19-13)/1000000) -> 66.000006
A20: Experience & Service Path | B20: =IF(B5<1,"",IF(Interests!$B$57="","",Interests!$B$57)) -> 55 | C20: =IF(B6<1,"",IF(Strengths!$B$57="","",Strengths!$B$57)) -> 50 | D20: =IF(B7<1,"",IF(Drivers!$B$61="","",Drivers!$B$61)) -> 50 | E20: =IF(B8<1,"",IF('Work Style & Environment'!$B$71="","",'Work Style & Environment'!$B$71)) -> 87 | F20: =IF($B$9=0,"",ROUND(B20*$E$5 + C20*$E$6 + D20*$E$7 + E20*$E$8,0)) -> 55 | G20: =IF($B$9=0,"",IF(F20>=Admin_Settings!$B$3,Admin_Settings!$B$7,IF(F20>=Admin_Settings!$B$4,Admin_Settings!$B$8,IF(F20>=Admin_Settings!$B$5,Admin_Settings!$B$9,IF(F20>=Admin_Settings!$B$6,Admin_Settings!$B$10,Admin_Settings!$B$11))))) -> Moderate Fit | H20: Delivering great experiences through hospitality, food service, events, retail, or customer service. You stay friendly and focused in busy environments and take pride in making people's day better. | I20: =IF($B$9=0,"",ROUND(B20*$E$5,1)) -> 19.3 | J20: =IF($B$9=0,"",ROUND(C20*$E$6,1)) -> 17.5 | K20: =IF($B$9=0,"",ROUND(D20*$E$7,1)) -> 10 | L20: =IF($B$9=0,"",ROUND(E20*$E$8,1)) -> 8.7 | M20: =IF($B$9=0,"","Top: " & IF(MAX(I20:L20)=I20,"Interests",IF(MAX(I20:L20)=J20,"Strengths",IF(MAX(I20:L20)=K20,"Drivers","Work Style & Environment")))) -> Top: Interests | O20: =IF($B$9=0,"",$F20+(20-13)/1000000) -> 55.000007
A21: Outdoor Systems Path | B21: =IF(B5<1,"",IF(Interests!$B$58="","",Interests!$B$58)) -> 25 | C21: =IF(B6<1,"",IF(Strengths!$B$58="","",Strengths!$B$58)) -> 25 | D21: =IF(B7<1,"",IF(Drivers!$B$62="","",Drivers!$B$62)) -> 25 | E21: =IF(B8<1,"",IF('Work Style & Environment'!$B$72="","",'Work Style & Environment'!$B$72)) -> 77 | F21: =IF($B$9=0,"",ROUND(B21*$E$5 + C21*$E$6 + D21*$E$7 + E21*$E$8,0)) -> 30 | G21: =IF($B$9=0,"",IF(F21>=Admin_Settings!$B$3,Admin_Settings!$B$7,IF(F21>=Admin_Settings!$B$4,Admin_Settings!$B$8,IF(F21>=Admin_Settings!$B$5,Admin_Settings!$B$9,IF(F21>=Admin_Settings!$B$6,Admin_Settings!$B$10,Admin_Settings!$B$11))))) -> Low Fit | H21: Working outdoors with land, water, animals, and natural systems to grow food, manage resources, and protect the environment. You value hands-on work with long-term purpose and connection to nature. | I21: =IF($B$9=0,"",ROUND(B21*$E$5,1)) -> 8.8 | J21: =IF($B$9=0,"",ROUND(C21*$E$6,1)) -> 8.8 | K21: =IF($B$9=0,"",ROUND(D21*$E$7,1)) -> 5 | L21: =IF($B$9=0,"",ROUND(E21*$E$8,1)) -> 7.7 | M21: =IF($B$9=0,"","Top: " & IF(MAX(I21:L21)=I21,"Interests",IF(MAX(I21:L21)=J21,"Strengths",IF(MAX(I21:L21)=K21,"Drivers","Work Style & Environment")))) -> Top: Interests | O21: =IF($B$9=0,"",$F21+(21-13)/1000000) -> 30.000008
A24: Top Paths to Explore (Top 3)
A25: Rank | B25: LifePath | C25: Overall | D25: Signal | H25: About this path
A26: 1 | B26: =IF($B$9=0,"",INDEX($A$13:$A$21,MATCH(LARGE($O$13:$O$21,1),$O$13:$O$21,0))) -> Learning & Support Path | C26: =IF($B$9=0,"",LARGE($F$13:$F$21,1)) -> 80 | D26: =IF($B$9=0,"",INDEX($G$13:$G$21,MATCH($B26,$A$13:$A$21,0))) -> Strong Fit | H26: =IF($B$9=0,"",IF(B26="","",INDEX($H$13:$H$21,MATCH(B26,$A$13:$A$21,0)))) -> Helping others learn, grow, and overcome challenges through teaching, counseling, coaching, or community programs. You build trust over time and take pride in watching people progress.
A27: 2 | B27: =IF($B$9=0,"",INDEX($A$13:$A$21,MATCH(LARGE($O$13:$O$21,2),$O$13:$O$21,0))) -> Business Growth & Leadership Path | C27: =IF($B$9=0,"",LARGE($F$13:$F$21,2)) -> 78 | D27: =IF($B$9=0,"",INDEX($G$13:$G$21,MATCH($B27,$A$13:$A$21,0))) -> Strong Fit | H27: =IF($B$9=0,"",IF(B27="","",INDEX($H$13:$H$21,MATCH(B27,$A$13:$A$21,0)))) -> Organizing people, plans, and resources to reach goals and grow organizations. You work in management, marketing, finance, entrepreneurship, or operations — making decisions that create results.
A28: 3 | B28: =IF($B$9=0,"",INDEX($A$13:$A$21,MATCH(LARGE($O$13:$O$21,3),$O$13:$O$21,0))) -> Clinical Care Path | C28: =IF($B$9=0,"",LARGE($F$13:$F$21,3)) -> 69 | D28: =IF($B$9=0,"",INDEX($G$13:$G$21,MATCH($B28,$A$13:$A$21,0))) -> Moderate Fit | H28: =IF($B$9=0,"",IF(B28="","",INDEX($H$13:$H$21,MATCH(B28,$A$13:$A$21,0)))) -> Helping people heal through nursing, therapy, medicine, or mental health care. You work directly with patients in clinical settings using careful procedures and science-based methods.
A29: =IF($B$9=0,"",IF(ABS($C26-$C27)<=Admin_Settings!$B$13,"Tie note: Your Top 2 are very close—explore BOTH.","")) -> Tie note: Your Top 2 are very close—explore BOTH.
A30: Next Steps Summary (Layered — student-friendly)
A31: Use this to talk with a counselor/teacher/family. These are starting points, not a final answer.
